Workbook

Sheet Автоматизированный расчет
A1: Script name | B1: transaction rq | C1: count | D1: VU | E1: pacing | F1: одним пользователем в минуту | G1: Длительность ступени | H1: Итого | I1: transaction rq | J1: Сумма по полю Итого | M1: Операция (бизнес процесс) | N1: Duration | O1: Think_time | P1: Duration + Think_time | Q1: Pacing | R1: VU | S1: % Распределения пользователей | T1: Jmeter, throughput per minute | U1: Длительность ступени в минутах | V1: Интенсивность операций | W1: Всего пользователей на ступени
A2: Покупка билета | B2: Главная Welcome страница | C2: 1 | D2: =VLOOKUP(A2,$M$1:$X$8,6,FALSE()) -> 4 | E2: =VLOOKUP(A2,$M$1:$X$8,5,FALSE()) -> 82.8 | F2: =60/E2*C2 -> 0.72463768 | G2: =VLOOKUP(A2,$M$1:$X$8,9,FALSE()) -> 20 | H2: =D2*F2*G2 -> 57.971014 | I2: Вход в систему | J2: 142.35499 | M2: Покупка билета | N2: 0.4 | O2: 41 | P2: =N2+O2 -> 41.4 | Q2: =P2*2 -> 82.8 | R2: 4 | S2: =R2/W$2 -> 0.4 | T2: =60/(Q2) -> 0.72463768 | U2: 20 | V2: =ROUND(R2*T2*U2,0) -> 58 | W2: =SUM(R2:R7) -> 10
A3: Покупка билета | B3: Вход в систему | C3: 1 | D3: =VLOOKUP(A3,$M$1:$X$8,6,FALSE()) -> 4 | E3: =VLOOKUP(A3,$M$1:$X$8,5,FALSE()) -> 82.8 | F3: =60/E3*C3 -> 0.72463768 | G3: =VLOOKUP(A3,$M$1:$X$8,9,FALSE()) -> 20 | H3: =D3*F3*G3 -> 57.971014 | I3: Выбор рейса из найденных | J3: 91.965349 | M3: Удаление бронирования | N3: 0.3 | O3: 24 | P3: =N3+O3 -> 24.3 | Q3: =P3*2 -> 48.6 | R3: 1 | S3: =R3/W$2 -> 0.1 | T3: =60/(Q3) -> 1.2345679 | U3: 20 | V3: =ROUND(R3*T3*U3,0) -> 25
A4: Покупка билета | B4: Переход на страницу поиска билетов | C4: 1 | D4: =VLOOKUP(A4,$M$1:$X$8,6,FALSE()) -> 4 | E4: =VLOOKUP(A4,$M$1:$X$8,5,FALSE()) -> 82.8 | F4: =60/E4*C4 -> 0.72463768 | G4: =VLOOKUP(A4,$M$1:$X$8,9,FALSE()) -> 20 | H4: =D4*F4*G4 -> 57.971014 | I4: Выход из системы | J4: 108.36065 | M4: Регистрация новых пользователей | N4: 0.2 | O4: 18 | P4: =N4+O4 -> 18.2 | Q4: =P4*2 -> 36.4 | R4: 1 | S4: =R4/W$2 -> 0.1 | T4: =60/(Q4) -> 1.6483516 | U4: 20 | V4: =ROUND(R4*T4*U4,0) -> 33
A5: Покупка билета | B5: Заполнение полей для поиска билета | C5: 1 | D5: =VLOOKUP(A5,$M$1:$X$8,6,FALSE()) -> 4 | E5: =VLOOKUP(A5,$M$1:$X$8,5,FALSE()) -> 82.8 | F5: =60/E5*C5 -> 0.72463768 | G5: =VLOOKUP(A5,$M$1:$X$8,9,FALSE()) -> 20 | H5: =D5*F5*G5 -> 57.971014 | I5: Заполнение полей для поиска билета | J5: 91.965349 | M5: Поиск билета без покупки | N5: 0.3 | O5: 35 | P5: =N5+O5 -> 35.3 | Q5: =P5*2 -> 70.6 | R5: 2 | S5: =R5/W$2 -> 0.2 | T5: =60/(Q5) -> 0.84985836 | U5: 20 | V5: =ROUND(R5*T5*U5,0) -> 34
A6: Покупка билета | B6: Выбор рейса из найденных | C6: 1 | D6: =VLOOKUP(A6,$M$1:$X$8,6,FALSE()) -> 4 | E6: =VLOOKUP(A6,$M$1:$X$8,5,FALSE()) -> 82.8 | F6: =60/E6*C6 -> 0.72463768 | G6: =VLOOKUP(A6,$M$1:$X$8,9,FALSE()) -> 20 | H6: =D6*F6*G6 -> 57.971014 | I6: Оплата билета | J6: 57.971014 | M6: Ознакомление с путевым листом | N6: 0.3 | O6: 60 | P6: =N6+O6 -> 60.3 | Q6: =P6*2 -> 120.6 | R6: 1 | S6: =R6/W$2 -> 0.1 | T6: =60/(Q6) -> 0.49751244 | U6: 20 | V6: =ROUND(R6*T6*U6,0) -> 10
A7: Покупка билета | B7: Оплата билета | C7: 1 | D7: =VLOOKUP(A7,$M$1:$X$8,6,FALSE()) -> 4 | E7: =VLOOKUP(A7,$M$1:$X$8,5,FALSE()) -> 82.8 | F7: =60/E7*C7 -> 0.72463768 | G7: =VLOOKUP(A7,$M$1:$X$8,9,FALSE()) -> 20 | H7: =D7*F7*G7 -> 57.971014 | I7: Отмена бронирования | J7: 24.691358 | M7: Логин | N7: 0.1 | O7: 38 | P7: =N7+O7 -> 38.1 | Q7: =P7*2 -> 76.2 | R7: 1 | S7: =R7/W$2 -> 0.1 | T7: =60/(Q7) -> 0.78740157 | U7: 20 | V7: =ROUND(R7*T7*U7,0) -> 16
A8: Покупка билета | B8: Просмотр квитанций | C8: 1 | D8: =VLOOKUP(A8,$M$1:$X$8,6,FALSE()) -> 4 | E8: =VLOOKUP(A8,$M$1:$X$8,5,FALSE()) -> 82.8 | F8: =60/E8*C8 -> 0.72463768 | G8: =VLOOKUP(A8,$M$1:$X$8,9,FALSE()) -> 20 | H8: =D8*F8*G8 -> 57.971014 | I8: Просмотр квитанций | J8: 92.612621 | S8: =SUM(S2:S7) -> 1 | V8: =SUM(V2:V7) -> 176
A9: Покупка билета | B9: Выход из системы | C9: 1 | D9: =VLOOKUP(A9,$M$1:$X$8,6,FALSE()) -> 4 | E9: =VLOOKUP(A9,$M$1:$X$8,5,FALSE()) -> 82.8 | F9: =60/E9*C9 -> 0.72463768 | G9: =VLOOKUP(A9,$M$1:$X$8,9,FALSE()) -> 20 | H9: =D9*F9*G9 -> 57.971014 | I9: Главная Welcome страница | J9: 175.32202
A10: Удаление бронирования | B10: Главная Welcome страница | C10: 1 | D10: =VLOOKUP(A10,$M$1:$X$8,6,FALSE()) -> 1 | E10: =VLOOKUP(A10,$M$1:$X$8,5,FALSE()) -> 48.6 | F10: =60/E10*C10 -> 1.2345679 | G10: =VLOOKUP(A10,$M$1:$X$8,9,FALSE()) -> 20 | H10: =D10*F10*G10 -> 24.691358 | I10: Перход на страницу регистрации | J10: 32.967033
A11: Удаление бронирования | B11: Вход в систему | C11: 1 | D11: =VLOOKUP(A11,$M$1:$X$8,6,FALSE()) -> 1 | E11: =VLOOKUP(A11,$M$1:$X$8,5,FALSE()) -> 48.6 | F11: =60/E11*C11 -> 1.2345679 | G11: =VLOOKUP(A11,$M$1:$X$8,9,FALSE()) -> 20 | H11: =D11*F11*G11 -> 24.691358 | I11: Заполнение полей регистарции | J11: 32.967033
A12: Удаление бронирования | B12: Просмотр квитанций | C12: 1 | D12: =VLOOKUP(A12,$M$1:$X$8,6,FALSE()) -> 1 | E12: =VLOOKUP(A12,$M$1:$X$8,5,FALSE()) -> 48.6 | F12: =60/E12*C12 -> 1.2345679 | G12: =VLOOKUP(A12,$M$1:$X$8,9,FALSE()) -> 20 | H12: =D12*F12*G12 -> 24.691358 | I12: Переход на следуюущий эран после регистарции | J12: 32.967033
A13: Удаление бронирования | B13: Отмена бронирования | C13: 1 | D13: =VLOOKUP(A13,$M$1:$X$8,6,FALSE()) -> 1 | E13: =VLOOKUP(A13,$M$1:$X$8,5,FALSE()) -> 48.6 | F13: =60/E13*C13 -> 1.2345679 | G13: =VLOOKUP(A13,$M$1:$X$8,9,FALSE()) -> 20 | H13: =D13*F13*G13 -> 24.691358 | I13: Переход на страницу поиска билетов | J13: 101.9156
A14: Удаление бронирования | B14: Выход из системы | C14: 1 | D14: =VLOOKUP(A14,$M$1:$X$8,6,FALSE()) -> 1 | E14: =VLOOKUP(A14,$M$1:$X$8,5,FALSE()) -> 48.6 | F14: =60/E14*C14 -> 1.2345679 | G14: =VLOOKUP(A14,$M$1:$X$8,9,FALSE()) -> 20 | H14: =D14*F14*G14 -> 24.691358 | I14: Total Result | J14: 986.06005
A15: Регистрация новых пользователей | B15: Главная Welcome страница | C15: 1 | D15: =VLOOKUP(A15,$M$1:$X$8,6,FALSE()) -> 1 | E15: =VLOOKUP(A15,$M$1:$X$8,5,FALSE()) -> 36.4 | F15: =60/E15*C15 -> 1.6483516 | G15: =VLOOKUP(A15,$M$1:$X$8,9,FALSE()) -> 20 | H15: =D15*F15*G15 -> 32.967033
A16: Регистрация новых пользователей | B16: Перход на страницу регистрации | C16: 1 | D16: =VLOOKUP(A16,$M$1:$X$8,6,FALSE()) -> 1 | E16: =VLOOKUP(A16,$M$1:$X$8,5,FALSE()) -> 36.4 | F16: =60/E16*C16 -> 1.6483516 | G16: =VLOOKUP(A16,$M$1:$X$8,9,FALSE()) -> 20 | H16: =D16*F16*G16 -> 32.967033
A17: Регистрация новых пользователей | B17: Заполнение полей регистарции | C17: 1 | D17: =VLOOKUP(A17,$M$1:$X$8,6,FALSE()) -> 1 | E17: =VLOOKUP(A17,$M$1:$X$8,5,FALSE()) -> 36.4 | F17: =60/E17*C17 -> 1.6483516 | G17: =VLOOKUP(A17,$M$1:$X$8,9,FALSE()) -> 20 | H17: =D17*F17*G17 -> 32.967033
A18: Регистрация новых пользователей | B18: Переход на следуюущий эран после регистарции | C18: 1 | D18: =VLOOKUP(A18,$M$1:$X$8,6,FALSE()) -> 1 | E18: =VLOOKUP(A18,$M$1:$X$8,5,FALSE()) -> 36.4 | F18: =60/E18*C18 -> 1.6483516 | G18: =VLOOKUP(A18,$M$1:$X$8,9,FALSE()) -> 20 | H18: =D18*F18*G18 -> 32.967033
A19: Регистрация новых пользователей | B19: Выход из системы | C19: 0 | D19: =VLOOKUP(A19,$M$1:$X$8,6,FALSE()) -> 1 | E19: =VLOOKUP(A19,$M$1:$X$8,5,FALSE()) -> 36.4 | F19: =60/E19*C19 -> 0 | G19: =VLOOKUP(A19,$M$1:$X$8,9,FALSE()) -> 20 | H19: =D19*F19*G19 -> 0
A20: Логин | B20: Главная Welcome страница | C20: 1 | D20: =VLOOKUP(A20,$M$1:$X$8,6,FALSE()) -> 1 | E20: =VLOOKUP(A20,$M$1:$X$8,5,FALSE()) -> 76.2 | F20: =60/E20*C20 -> 0.78740157 | G20: =VLOOKUP(A20,$M$1:$X$8,9,FALSE()) -> 20 | H20: =D20*F20*G20 -> 15.748031
A21: Логин | B21: Вход в систему | C21: 1 | D21: =VLOOKUP(A21,$M$1:$X$8,6,FALSE()) -> 1 | E21: =VLOOKUP(A21,$M$1:$X$8,5,FALSE()) -> 76.2 | F21: =60/E21*C21 -> 0.78740157 | G21: =VLOOKUP(A21,$M$1:$X$8,9,FALSE()) -> 20 | H21: =D21*F21*G21 -> 15.748031
A22: Логин | B22: Просмотр квитанций | C22: 0 | D22: =VLOOKUP(A22,$M$1:$X$8,6,FALSE()) -> 1 | E22: =VLOOKUP(A22,$M$1:$X$8,5,FALSE()) -> 76.2 | F22: =60/E22*C22 -> 0 | G22: =VLOOKUP(A22,$M$1:$X$8,9,FALSE()) -> 20 | H22: =D22*F22*G22 -> 0
A23: Логин | B23: Выход из системы | C23: 1 | D23: =VLOOKUP(A23,$M$1:$X$8,6,FALSE()) -> 1 | E23: =VLOOKUP(A23,$M$1:$X$8,5,FALSE()) -> 76.2 | F23: =60/E23*C23 -> 0.78740157 | G23: =VLOOKUP(A23,$M$1:$X$8,9,FALSE()) -> 20 | H23: =D23*F23*G23 -> 15.748031
A24: Поиск билета без покупки | B24: Главная Welcome страница | C24: 1 | D24: =VLOOKUP(A24,$M$1:$X$8,6,FALSE()) -> 2 | E24: =VLOOKUP(A24,$M$1:$X$8,5,FALSE()) -> 70.6 | F24: =60/E24*C24 -> 0.84985836 | G24: =VLOOKUP(A24,$M$1:$X$8,9,FALSE()) -> 20 | H24: =D24*F24*G24 -> 33.994334
A25: Поиск билета без покупки | B25: Вход в систему | C25: 1 | D25: =VLOOKUP(A25,$M$1:$X$8,6,FALSE()) -> 2 | E25: =VLOOKUP(A25,$M$1:$X$8,5,FALSE()) -> 70.6 | F25: =60/E25*C25 -> 0.84985836 | G25: =VLOOKUP(A25,$M$1:$X$8,9,FALSE()) -> 20 | H25: =D25*F25*G25 -> 33.994334
A26: Поиск билета без покупки | B26: Переход на страницу поиска билетов | C26: 1 | D26: =VLOOKUP(A26,$M$1:$X$8,6,FALSE()) -> 2 | E26: =VLOOKUP(A26,$M$1:$X$8,5,FALSE()) -> 70.6 | F26: =60/E26*C26 -> 0.84985836 | G26: =VLOOKUP(A26,$M$1:$X$8,9,FALSE()) -> 20 | H26: =D26*F26*G26 -> 33.994334
... A35: Ознакомление с путевым листом | B35: Выход из системы | C35: 1 | D35: =VLOOKUP(A35,$M$1:$X$8,6,FALSE()) -> 1 | E35: =VLOOKUP(A35,$M$1:$X$8,5,FALSE()) -> 120.6 | F35: =60/E35*C35 -> 0.49751244 | G35: =VLOOKUP(A35,$M$1:$X$8,9,FALSE()) -> 20 | H35: =D35*F35*G35 -> 9.9502488
A37: Статистика с ПРОДа | C37: Профиль
A38: Название запроса | B38: Интенсивность по статистике запросов / час | C38: Расчетная интенсивность запросов / час | D38: % Соотвествия расчетанной интенсивности статистики | F38: ScriptName | G38: Расчетная интенсивность запросов / 20 мин | H38: Фактическая интенсивность в тесте | I38: % Отклонение от Профиля
A39: Главная Welcome страница | B39: 520 | C39: =GETPIVOTDATA("Итого",$I$1,"transaction rq",A39)*3 -> 525.96606 | D39: =1-B39/C39 -> 0.011343051 | F39: =VLOOKUP(A39,Соответствие!A:B,2,FALSE()) -> TF_home_page | G39: =GETPIVOTDATA("Итого",$I$1,"transaction rq",A39) -> 175.32202 | H39: =SummaryReport!B9 -> 174 | I39: =1-G39/H39 -> -0.0075978162
A40: Вход в систему | B40: 422 | C40: =GETPIVOTDATA("Итого",$I$1,"transaction rq",A40)*3 -> 427.06496 | D40: =1-B40/C40 -> 0.011859931 | F40: =VLOOKUP(A40,Соответствие!A:B,2,FALSE()) -> TF_login | G40: =GETPIVOTDATA("Итого",$I$1,"transaction rq",A40) -> 142.35499 | H40: =SummaryReport!B2 -> 143 | I40: =1-G40/H40 -> 0.0045105801
A41: Переход на страницу поиска билетов | B41: 305 | C41: =GETPIVOTDATA("Итого",$I$1,"transaction rq",A41)*3 -> 305.74679 | D41: =1-B41/C41 -> 0.0024425198 | F41: =VLOOKUP(A41,Соответствие!A:B,2,FALSE()) -> TF_flights | G41: =GETPIVOTDATA("Итого",$I$1,"transaction rq",A41) -> 101.9156 | H41: =SummaryReport!B8 -> 101 | I41: =1-G41/H41 -> -0.009065322
A42: Заполнение полей для поиска билета | B42: 282 | C42: =GETPIVOTDATA("Итого",$I$1,"transaction rq",A42)*3 -> 275.89605 | D42: =1-B42/C42 -> -0.022124107 | F42: =VLOOKUP(A42,Соответствие!A:B,2,FALSE()) -> TF_flights_find | G42: =GETPIVOTDATA("Итого",$I$1,"transaction rq",A42) -> 91.965349 | H42: =SummaryReport!B10 -> 91 | I42: =1-G42/H42 -> -0.010608228
A43: Выбор рейса из найденных | B43: 270 | C43: =GETPIVOTDATA("Итого",$I$1,"transaction rq",A43)*3 -> 275.89605 | D43: =1-B43/C43 -> 0.021370536 | F43: =VLOOKUP(A43,Соответствие!A:B,2,FALSE()) -> TF_choose_available_flight | G43: =GETPIVOTDATA("Итого",$I$1,"transaction rq",A43) -> 91.965349 | H43: =SummaryReport!B6 -> 91 | I43: =1-G43/H43 -> -0.010608228
A44: Оплата билета | B44: 175 | C44: =GETPIVOTDATA("Итого",$I$1,"transaction rq",A44)*3 -> 173.91304 | D44: =1-B44/C44 -> -0.00625 | F44: =VLOOKUP(A44,Соответствие!A:B,2,FALSE()) -> TF_payment_details | G44: =GETPIVOTDATA("Итого",$I$1,"transaction rq",A44) -> 57.971014 | H44: =SummaryReport!B4 -> 57 | I44: =1-G44/H44 -> -0.017035342
A45: Просмотр квитанций | B45: 280 | C45: =GETPIVOTDATA("Итого",$I$1,"transaction rq",A45)*3 -> 277.83786 | D45: =1-B45/C45 -> -0.0077820069 | F45: =VLOOKUP(A45,Соответствие!A:B,2,FALSE()) -> TF_itinerary | G45: =GETPIVOTDATA("Итого",$I$1,"transaction rq",A45) -> 92.612621 | H45: =SummaryReport!B7 -> 92 | I45: =1-G45/H45 -> -0.0066589269
A46: Отмена бронирования | B46: 73 | C46: =GETPIVOTDATA("Итого",$I$1,"transaction rq",A46)*3 -> 74.074074 | D46: =1-B46/C46 -> 0.0145 | F46: =VLOOKUP(A46,Соответствие!A:B,2,FALSE()) -> TF_itinerary_delete_one (first) | G46: =GETPIVOTDATA("Итого",$I$1,"transaction rq",A46) -> 24.691358 | H46: =SummaryReport!B5 -> 25 | I46: =1-G46/H46 -> 0.012345679
A47: Выход из системы | B47: 326 | C47: =GETPIVOTDATA("Итого",$I$1,"transaction rq",A47)*3 -> 325.08196 | D47: =1-B47/C47 -> -0.0028240315 | F47: =VLOOKUP(A47,Соответствие!A:B,2,FALSE()) -> TF_logout | G47: =GETPIVOTDATA("Итого",$I$1,"transaction rq",A47) -> 108.36065 | H47: =SummaryReport!B3 -> 108 | I47: =1-G47/H47 -> -0.0033393775
A48: Перход на страницу регистрации | B48: 97 | C48: =GETPIVOTDATA("Итого",$I$1,"transaction rq",A48)*3 -> 98.901099 | D48: =1-B48/C48 -> 0.019222222 | F48: =VLOOKUP(A48,Соответствие!A:B,2,FALSE()) -> TF_open_register_page | G48: =GETPIVOTDATA("Итого",$I$1,"transaction rq",A48) -> 32.967033 | H48: =SummaryReport!B11 -> 32 | I48: =1-G48/H48 -> -0.03021978
A49: Заполнение полей регистарции | B49: 97 | C49: =GETPIVOTDATA("Итого",$I$1,"transaction rq",A49)*3 -> 98.901099 | D49: =1-B49/C49 -> 0.019222222 | F49: =VLOOKUP(A49,Соответствие!A:B,2,FALSE()) -> TF_fill_register_page | G49: =GETPIVOTDATA("Итого",$I$1,"transaction rq",A49) -> 32.967033 | H49: =SummaryReport!B12 -> 32 | I49: =1-G49/H49 -> -0.03021978
...

Sheet Соответствие
A1: Имя в статистике | B1: Имя в скрипте
A2: ='Автоматизированный расчет'!A39 -> Главная Welcome страница | B2: TF_home_page
A3: ='Автоматизированный расчет'!A40 -> Вход в систему | B3: TF_login
A4: ='Автоматизированный расчет'!A41 -> Переход на страницу поиска билетов | B4: TF_flights
A5: ='Автоматизированный расчет'!A42 -> Заполнение полей для поиска билета | B5: TF_flights_find
A6: ='Автоматизированный расчет'!A43 -> Выбор рейса из найденных | B6: TF_choose_available_flight
A7: ='Автоматизированный расчет'!A44 -> Оплата билета | B7: TF_payment_details
A8: ='Автоматизированный расчет'!A45 -> Просмотр квитанций | B8: TF_itinerary
A9: ='Автоматизированный расчет'!A46 -> Отмена бронирования | B9: TF_itinerary_delete_one (first)
A10: ='Автоматизированный расчет'!A47 -> Выход из системы | B10: TF_logout
A11: ='Автоматизированный расчет'!A48 -> Перход на страницу регистрации | B11: TF_open_register_page
A12: ='Автоматизированный расчет'!A49 -> Заполнение полей регистарции | B12: TF_fill_register_page
A13: ='Автоматизированный расчет'!A50 -> Переход на следуюущий эран после регистарции | B13: TF_next_page_after_register_completion

Sheet SummaryReport
A2: TC_login | B2: 143 | E2: профиль для 10 пользователей (отладочный тест 22 мин)
A3: TC_logout | B3: 108 | E3: Requests | F3: Executions | K3: Response Time (ms)
A4: TC_payment_details | B4: 57 | F4: Total | G4: OK | H4: KO | I4: % KO | J4: Cnt/s | K4: Min | L4: 50th pct | M4: 75th pct | N4: 90th pct | O4: 99th pct | P4: Max | Q4: Mean | R4: Std Dev
A5: TC_itinerary_delete_one (first) | B5: 25 | E5: All Requests | F5: 2424 | G5: 2424 | H5: 0 | I5: 0.00 | J5: 1.85 | K5: 1 | L5: 30 | M5: 81 | N5: 97 | O5: 342 | P5: 677 | Q5: 54 | R5: 63
A6: TC_choose_available_flight | B6: 91 | E6: home_page | F6: 195 | G6: 195 | H6: 0 | I6: 0.00 | J6: 0.15 | K6: 49 | L6: 98 | M6: 112 | N6: 136 | O6: 857 | P6: 948 | Q6: 129 | R6: 163
A7: TC_itinerary | B7: 92 | E7: /WebTours/ | F7: 195 | G7: 195 | H7: 0 | I7: 0.00 | J7: 0.15 | K7: 1 | L7: 2 | M7: 2 | N7: 2 | O7: 50 | P7: 50 | Q7: 2 | R7: 5
A8: TC_flights | B8: 101 | E8: /cgi-bin/welcome.pl | F8: 195 | G8: 195 | H8: 0 | I8: 0.00 | J8: 0.15 | K8: 21 | L8: 23 | M8: 23 | N8: 43 | O8: 595 | P8: 595 | Q8: 40 | R8: 77
A9: TC_home_page | B9: 174 | E9: /cgi-bin/nav.pl | F9: 195 | G9: 195 | H9: 0 | I9: 0.00 | J9: 0.15 | K9: 24 | L9: 73 | M9: 87 | N9: 95 | O9: 677 | P9: 677 | Q9: 84 | R9: 101
A10: TC_flights_find | B10: 91 | E10: login | F10: 158 | G10: 158 | H10: 0 | I10: 0.00 | J10: 0.12 | K10: 132 | L10: 184 | M10: 217 | N10: 402 | O10: 1225 | P10: 1345 | Q10: 248 | R10: 221
A11: TC_open_register_page | B11: 32 | E11: /cgi-bin/login.pl | F11: 316 | G11: 316 | H11: 0 | I11: 0.00 | J11: 0.24 | K11: 25 | L11: 87 | M11: 93 | N11: 136 | O11: 470 | P11: 597 | Q11: 82 | R11: 82
A12: TC_fill_register_page | B12: 32 | E12: /cgi-bin/nav.pl | F12: 158 | G12: 158 | H12: 0 | I12: 0.00 | J12: 0.12 | K12: 24 | L12: 64 | M12: 86 | N12: 113 | O12: 401 | P12: 498 | Q12: 77 | R12: 77
A13: TC_next_page_after_register_completion | B13: 32 | E13: open_register_page | F13: 37 | G13: 37 | H13: 0 | I13: 0.00 | J13: 0.03 | K13: 27 | L13: 28 | M13: 28 | N13: 29 | O13: 452 | P13: 452 | Q13: 40 | R13: 69
E14: /cgi-bin/login.pl | F14: 37 | G14: 37 | H14: 0 | I14: 0.00 | J14: 0.03 | K14: 27 | L14: 28 | M14: 28 | N14: 29 | O14: 452 | P14: 452 | Q14: 40 | R14: 69
E15: fill_register_page | F15: 37 | G15: 37 | H15: 0 | I15: 0.00 | J15: 0.03 | K15: 28 | L15: 29 | M15: 30 | N15: 30 | O15: 101 | P15: 101 | Q15: 34 | R15: 16
E16: /cgi-bin/login.pl | F16: 37 | G16: 37 | H16: 0 | I16: 0.00 | J16: 0.03 | K16: 28 | L16: 29 | M16: 30 | N16: 30 | O16: 101 | P16: 101 | Q16: 34 | R16: 16
E17: flights | F17: 113 | G17: 113 | H17: 0 | I17: 0.00 | J17: 0.09 | K17: 74 | L17: 147 | M17: 215 | N17: 304 | O17: 464 | P17: 533 | Q17: 183 | R17: 88
E18: /cgi-bin/welcome.pl | F18: 113 | G18: 113 | H18: 0 | I18: 0.00 | J18: 0.09 | K18: 19 | L18: 20 | M18: 21 | N18: 79 | O18: 159 | P18: 167 | Q18: 32 | R18: 32
E19: /cgi-bin/nav.pl | F19: 113 | G19: 113 | H19: 0 | I19: 0.00 | J19: 0.09 | K19: 24 | L19: 53 | M19: 79 | N19: 106 | O19: 200 | P19: 201 | Q19: 63 | R19: 43
E20: /cgi-bin/reservations.pl | F20: 113 | G20: 113 | H20: 0 | I20: 0.00 | J20: 0.09 | K20: 28 | L20: 94 | M20: 96 | N20: 111 | O20: 282 | P20: 295 | Q20: 88 | R20: 47
E21: itinerary | F21: 102 | G21: 102 | H21: 0 | I21: 0.00 | J21: 0.08 | K21: 75 | L21: 141 | M21: 200 | N21: 292 | O21: 503 | P21: 526 | Q21: 182 | R21: 88
E22: /cgi-bin/welcome.pl | F22: 102 | G22: 102 | H22: 0 | I22: 0.00 | J22: 0.08 | K22: 20 | L22: 21 | M22: 22 | N22: 63 | O22: 128 | P22: 162 | Q22: 30 | R22: 25
E23: /cgi-bin/itinerary.pl | F23: 102 | G23: 102 | H23: 0 | I23: 0.00 | J23: 0.08 | K23: 27 | L23: 69 | M23: 90 | N23: 109 | O23: 202 | P23: 206 | Q23: 73 | R23: 43
E24: /cgi-bin/nav.pl | F24: 102 | G24: 102 | H24: 0 | I24: 0.00 | J24: 0.08 | K24: 24 | L24: 78 | M24: 90 | N24: 105 | O24: 194 | P24: 197 | Q24: 66 | R24: 45
E25: logout | F25: 120 | G25: 120 | H25: 0 | I25: 0.00 | J25: 0.09 | K25: 46 | L25: 78 | M25: 102 | N25: 118 | O25: 291 | P25: 325 | Q25: 85 | R25: 47
... E39: /cgi-bin/reservations.pl | F39: 64 | G39: 64 | H39: 0 | I39: 0.00 | J39: 0.05 | K39: 30 | L39: 31 | M39: 32 | N39: 55 | O39: 176 | P39: 176 | Q39: 37 | R39: 21
E40: Сумма | F40: =F6+F10+F13+F15+F17+F21+F25+F28+F32+F34+F36+F38 -> 1094
E42: тест поиска максимальной производительности (6 ступень из 10 в тесте)
E43: Requests | F43: Executions | K43: Response Time (ms)
F44: Total | G44: OK | H44: KO | I44: % KO | J44: Cnt/s | K44: Min | L44: 50th pct | M44: 75th pct | N44: 90th pct | O44: 99th pct | P44: Max | Q44: Mean | R44: Std Dev
E45: All Requests | F45: 88305 | G45: 55152 | H45: 33153 | I45: 37.54 | J45: 6.32 | K45: 0 | L45: 190 | M45: 10001 | N45: 10001 | O45: 45329 | P45: 60002 | Q45: 4667 | R45: 8629
E46: home_page | F46: 7298 | G46: 4432 | H46: 2866 | I46: 39.27 | J46: 0.52 | K46: 48 | L46: 451 | M46: 30003 | N46: 30004 | O46: 129528 | P46: 211895 | Q46: 15181 | R46: 26352
E47: /WebTours/ | F47: 7319 | G47: 4462 | H47: 2857 | I47: 39.04 | J47: 0.52 | K47: 0 | L47: 19 | M47: 10001 | N47: 10001 | O47: 50698 | P47: 60002 | Q47: 4953 | R47: 9254
E48: /cgi-bin/welcome.pl | F48: 7312 | G48: 4435 | H48: 2877 | I48: 39.35 | J48: 0.52 | K48: 21 | L48: 195 | M48: 10001 | N48: 10001 | O48: 48189 | P48: 60002 | Q48: 5108 | R48: 9534
E49: /cgi-bin/nav.pl | F49: 7301 | G49: 4432 | H49: 2869 | I49: 39.30 | J49: 0.52 | K49: 24 | L49: 240 | M49: 10001 | N49: 10001 | O49: 46376 | P49: 60002 | Q49: 5045 | R49: 9227
E50: login | F50: 6029 | G50: 3588 | H50: 2441 | I50: 40.49 | J50: 0.43 | K50: 77 | L50: 649 | M50: 30002 | N50: 30004 | O50: 110416 | P50: 180003 | Q50: 14110 | R50: 24431
E51: /cgi-bin/login.pl | F51: 11500 | G51: 7180 | H51: 4320 | I51: 37.57 | J51: 0.82 | K51: 25 | L51: 200 | M51: 10001 | N51: 10001 | O51: 44371 | P51: 60002 | Q51: 4781 | R51: 8988
E52: /cgi-bin/nav.pl | F52: 6035 | G52: 3591 | H52: 2444 | I52: 40.50 | J52: 0.43 | K52: 24 | L52: 205 | M52: 10001 | N52: 10001 | O52: 53062 | P52: 60002 | Q52: 5005 | R52: 8774
E53: flights | F53: 4274 | G53: 2573 | H53: 1701 | I53: 39.80 | J53: 0.31 | K53: 73 | L53: 520 | M53: 30003 | N53: 30004 | O53: 126797 | P53: 180003 | Q53: 14545 | R53: 23539
E54: /cgi-bin/welcome.pl | F54: 4288 | G54: 2575 | H54: 1713 | I54: 39.95 | J54: 0.31 | K54: 19 | L54: 145 | M54: 10001 | N54: 10001 | O54: 57953 | P54: 60002 | Q54: 5006 | R54: 9091
E55: /cgi-bin/nav.pl | F55: 4280 | G55: 2575 | H55: 1705 | I55: 39.84 | J55: 0.31 | K55: 24 | L55: 195 | M55: 10001 | N55: 10001 | O55: 48546 | P55: 60002 | Q55: 4849 | R55: 8486
...

Sheet Результаты всех тестов
E2: Jmeter | L2: Gatling
E3: Профиль для 10 пользователей | L3: Профиль для 10 пользователей
E5: Наименование операции | F5: Наименование транзакции | G5: По профилю | H5: По факту | I5: % отклонения | L5: Наименование операции | M5: Наименование транзакции | N5: По профилю | O5: По факту | P5: % отклонения
E6: Главная Welcome страница | F6: TF_home_page | G6: ='Автоматизированный расчет'!C39 -> 525.96606 | H6: =('Автоматизированный расчет'!H39)*3 -> 522 | I6: =1-G6/H6 -> -0.0075978162 | L6: Главная Welcome страница | M6: TF_home_page | N6: ='Автоматизированный расчет'!C39 -> 525.96606 | O6: =((SummaryReport!F6)/22)*60 -> 531.81818 | P6: =1-N6/O6 -> 0.01100399
E7: Вход в систему | F7: TF_login | G7: ='Автоматизированный расчет'!C40 -> 427.06496 | H7: =('Автоматизированный расчет'!H40)*3 -> 429 | I7: =1-G7/H7 -> 0.0045105801 | L7: Вход в систему | M7: TF_login | N7: ='Автоматизированный расчет'!C40 -> 427.06496 | O7: =((SummaryReport!F10)/22)*60 -> 430.90909 | P7: =1-N7/O7 -> 0.0089209763
E8: Переход на страницу поиска билетов | F8: TF_flights | G8: ='Автоматизированный расчет'!C41 -> 305.74679 | H8: =('Автоматизированный расчет'!H41)*3 -> 303 | I8: =1-G8/H8 -> -0.009065322 | L8: Переход на страницу поиска билетов | M8: TF_flights | N8: ='Автоматизированный расчет'!C41 -> 305.74679 | O8: =((SummaryReport!F17)/22)*60 -> 308.18182 | P8: =1-N8/O8 -> 0.007901263
E9: Заполнение полей для поиска билета | F9: TF_flights_find | G9: ='Автоматизированный расчет'!C42 -> 275.89605 | H9: =('Автоматизированный расчет'!H42)*3 -> 273 | I9: =1-G9/H9 -> -0.010608228 | L9: Заполнение полей для поиска билета | M9: TF_flights_find | N9: ='Автоматизированный расчет'!C42 -> 275.89605 | O9: =((SummaryReport!F32)/22)*60 -> 278.18182 | P9: =1-N9/O9 -> 0.008216827
E10: Выбор рейса из найденных | F10: TF_choose_available_flight | G10: ='Автоматизированный расчет'!C43 -> 275.89605 | H10: =('Автоматизированный расчет'!H43)*3 -> 273 | I10: =1-G10/H10 -> -0.010608228 | L10: Выбор рейса из найденных | M10: TF_choose_available_flight | N10: ='Автоматизированный расчет'!C43 -> 275.89605 | O10: =((SummaryReport!F36)/22)*60 -> 278.18182 | P10: =1-N10/O10 -> 0.008216827
E11: Оплата билета | F11: TF_payment_details | G11: ='Автоматизированный расчет'!C44 -> 173.91304 | H11: =('Автоматизированный расчет'!H44)*3 -> 171 | I11: =1-G11/H11 -> -0.017035342 | L11: Оплата билета | M11: TF_payment_details | N11: ='Автоматизированный расчет'!C44 -> 173.91304 | O11: =((SummaryReport!F38)/22)*60 -> 174.54545 | P11: =1-N11/O11 -> 0.0036231884
E12: Просмотр квитанций | F12: TF_itinerary | G12: ='Автоматизированный расчет'!C45 -> 277.83786 | H12: =('Автоматизированный расчет'!H45)*3 -> 276 | I12: =1-G12/H12 -> -0.0066589269 | L12: Просмотр квитанций | M12: TF_itinerary | N12: ='Автоматизированный расчет'!C45 -> 277.83786 | O12: =((SummaryReport!F21)/22)*60 -> 278.18182 | P12: =1-N12/O12 -> 0.0012364372
E13: Отмена бронирования | F13: TF_itinerary_delete_one (first) | G13: ='Автоматизированный расчет'!C46 -> 74.074074 | H13: =('Автоматизированный расчет'!H46)*3 -> 75 | I13: =1-G13/H13 -> 0.012345679 | L13: Отмена бронирования | M13: TF_itinerary_delete_one (first) | N13: ='Автоматизированный расчет'!C46 -> 74.074074 | O13: =((SummaryReport!F34)/22)*60 -> 73.636364 | P13: =1-N13/O13 -> -0.0059442158
E14: Выход из системы | F14: TF_logout | G14: ='Автоматизированный расчет'!C47 -> 325.08196 | H14: =('Автоматизированный расчет'!H47)*3 -> 324 | I14: =1-G14/H14 -> -0.0033393775 | L14: Выход из системы | M14: TF_logout | N14: ='Автоматизированный расчет'!C47 -> 325.08196 | O14: =((SummaryReport!F25)/22)*60 -> 327.27273 | P14: =1-N14/O14 -> 0.0066940163
E15: Перход на страницу регистрации | F15: TF_open_register_page | G15: ='Автоматизированный расчет'!C48 -> 98.901099 | H15: =('Автоматизированный расчет'!H48)*3 -> 96 | I15: =1-G15/H15 -> -0.03021978 | L15: Перход на страницу регистрации | M15: TF_open_register_page | N15: ='Автоматизированный расчет'!C48 -> 98.901099 | O15: =((SummaryReport!F13)/22)*60 -> 100.90909 | P15: =1-N15/O15 -> 0.01989902
E16: Заполнение полей регистарции | F16: TF_fill_register_page | G16: ='Автоматизированный расчет'!C49 -> 98.901099 | H16: =('Автоматизированный расчет'!H49)*3 -> 96 | I16: =1-G16/H16 -> -0.03021978 | L16: Заполнение полей регистарции | M16: TF_fill_register_page | N16: ='Автоматизированный расчет'!C49 -> 98.901099 | O16: =((SummaryReport!F15)/22)*60 -> 100.90909 | P16: =1-N16/O16 -> 0.01989902
E17: Переход на следуюущий эран после регистарции | F17: TF_next_page_after_register_completion | G17: ='Автоматизированный расчет'!C50 -> 98.901099 | H17: =('Автоматизированный расчет'!H50)*3 -> 96 | I17: =1-G17/H17 -> -0.03021978 | L17: Переход на следуюущий эран после регистарции | M17: TF_next_page_after_register_completion | N17: ='Автоматизированный расчет'!C50 -> 98.901099 | O17: =((SummaryReport!F28)/22)*60 -> 100.90909 | P17: =1-N17/O17 -> 0.01989902
E18: Сумма | G18: =SUM(G6:G17) -> 2958.1801 | H18: =SUM(H6:H17) -> 2934 | I18: =1-G18/H18 -> -0.0082413575 | L18: Сумма | N18: =SUM(N6:N17) -> 2958.1801 | O18: =((SummaryReport!F40)/22)*60 -> 2983.6364 | P18: =1-N18/O18 -> 0.0085319448
E22: Поиск максимума 4 ступень | L22: Поиск максимума 6 ступень
E24: Наименование операции | F24: Наименование транзакции | G24: По профилю | H24: По факту | I24: % отклонения | L24: Наименование операции | M24: Наименование транзакции | N24: По профилю | O24: По факту | P24: % отклонения
E25: Главная Welcome страница | F25: TF_home_page | G25: ='Автоматизированный расчет'!C39 -> 525.96606 | H25: 2106 | I25: =H25/G25 -> 4.0040606 | L25: Главная Welcome страница | M25: TF_home_page | N25: ='Автоматизированный расчет'!C39 -> 525.96606 | P25: =O25/N25 -> 0
E26: Вход в систему | F26: TF_login | G26: ='Автоматизированный расчет'!C40 -> 427.06496 | H26: 1707 | I26: =H26/G26 -> 3.99705 | L26: Вход в систему | M26: TF_login | N26: ='Автоматизированный расчет'!C40 -> 427.06496 | P26: =O26/N26 -> 0
E27: Переход на страницу поиска билетов | F27: TF_flights | G27: ='Автоматизированный расчет'!C41 -> 305.74679 | H27: 1218 | I27: =H27/G27 -> 3.9836886 | L27: Переход на страницу поиска билетов | M27: TF_flights | N27: ='Автоматизированный расчет'!C41 -> 305.74679 | P27: =O27/N27 -> 0
E28: Заполнение полей для поиска билета | F28: TF_flights_find | G28: ='Автоматизированный расчет'!C42 -> 275.89605 | H28: 1098 | I28: =H28/G28 -> 3.9797598 | L28: Заполнение полей для поиска билета | M28: TF_flights_find | N28: ='Автоматизированный расчет'!C42 -> 275.89605 | P28: =O28/N28 -> 0
E29: Выбор рейса из найденных | F29: TF_choose_available_flight | G29: ='Автоматизированный расчет'!C43 -> 275.89605 | H29: 1095 | I29: =H29/G29 -> 3.9688862 | L29: Выбор рейса из найденных | M29: TF_choose_available_flight | N29: ='Автоматизированный расчет'!C43 -> 275.89605 | P29: =O29/N29 -> 0
E30: Оплата билета | F30: TF_payment_details | G30: ='Автоматизированный расчет'!C44 -> 173.91304 | H30: 690 | I30: =H30/G30 -> 3.9675 | L30: Оплата билета | M30: TF_payment_details | N30: ='Автоматизированный расчет'!C44 -> 173.91304 | P30: =O30/N30 -> 0
E31: Просмотр квитанций | F31: TF_itinerary | G31: ='Автоматизированный расчет'!C45 -> 277.83786 | H31: 1116 | I31: =H31/G31 -> 4.0167311 | L31: Просмотр квитанций | M31: TF_itinerary | N31: ='Автоматизированный расчет'!C45 -> 277.83786 | P31: =O31/N31 -> 0
E32: Отмена бронирования | F32: TF_itinerary_delete_one (first) | G32: ='Автоматизированный расчет'!C46 -> 74.074074 | H32: 300 | I32: =H32/G32 -> 4.05 | L32: Отмена бронирования | M32: TF_itinerary_delete_one (first) | N32: ='Автоматизированный расчет'!C46 -> 74.074074 | P32: =O32/N32 -> 0
E33: Выход из системы | F33: TF_logout | G33: ='Автоматизированный расчет'!C47 -> 325.08196 | H33: 1302 | I33: =H33/G33 -> 4.0051438 | L33: Выход из системы | M33: TF_logout | N33: ='Автоматизированный расчет'!C47 -> 325.08196 | P33: =O33/N33 -> 0
E34: Перход на страницу регистрации | F34: TF_open_register_page | G34: ='Автоматизированный расчет'!C48 -> 98.901099 | H34: 396 | I34: =H34/G34 -> 4.004 | L34: Перход на страницу регистрации | M34: TF_open_register_page | N34: ='Автоматизированный расчет'!C48 -> 98.901099 | P34: =O34/N34 -> 0
E35: Заполнение полей регистарции | F35: TF_fill_register_page | G35: ='Автоматизированный расчет'!C49 -> 98.901099 | H35: 396 | I35: =H35/G35 -> 4.004 | L35: Заполнение полей регистарции | M35: TF_fill_register_page | N35: ='Автоматизированный расчет'!C49 -> 98.901099 | P35: =O35/N35 -> 0
E36: Переход на следуюущий эран после регистарции | F36: TF_next_page_after_register_completion | G36: ='Автоматизированный расчет'!C50 -> 98.901099 | H36: 396 | I36: =H36/G36 -> 4.004 | L36: Переход на следуюущий эран после регистарции | M36: TF_next_page_after_register_completion | N36: ='Автоматизированный расчет'!C50 -> 98.901099 | P36: =O36/N36 -> 0
E37: Сумма | G37: =SUM(G25:G36) -> 2958.1801 | H37: 11820 | I37: =H37/G37 -> 3.9956999 | L37: Сумма | N37: =SUM(N25:N36) -> 2958.1801 | P37: =O37/N37 -> 0
E41: Подтверждение максимума | L41: Подтверждение максимума
E43: Наименование операции | F43: Наименование транзакции | G43: По профилю | H43: По факту | I43: % отклонения | L43: Наименование операции | M43: Наименование транзакции | N43: По профилю | O43: По факту | P43: % отклонения
E44: Главная Welcome страница | F44: TF_home_page | G44: ='Автоматизированный расчет'!C39 -> 525.96606 | H44: 2099 | I44: =H44/G44 -> 3.9907518 | L44: Главная Welcome страница | M44: TF_home_page | N44: ='Автоматизированный расчет'!C39 -> 525.96606 | P44: =O44/N44 -> 0
E45: Вход в систему | F45: TF_login | G45: ='Автоматизированный расчет'!C40 -> 427.06496 | H45: 1703 | I45: =H45/G45 -> 3.9876837 | L45: Вход в систему | M45: TF_login | N45: ='Автоматизированный расчет'!C40 -> 427.06496 | P45: =O45/N45 -> 0
E46: Переход на страницу поиска билетов | F46: TF_flights | G46: ='Автоматизированный расчет'!C41 -> 305.74679 | H46: 1217 | I46: =H46/G46 -> 3.9804179 | L46: Переход на страницу поиска билетов | M46: TF_flights | N46: ='Автоматизированный расчет'!C41 -> 305.74679 | P46: =O46/N46 -> 0
E47: Заполнение полей для поиска билета | F47: TF_flights_find | G47: ='Автоматизированный расчет'!C42 -> 275.89605 | H47: 1098 | I47: =H47/G47 -> 3.9797598 | L47: Заполнение полей для поиска билета | M47: TF_flights_find | N47: ='Автоматизированный расчет'!C42 -> 275.89605 | P47: =O47/N47 -> 0
E48: Выбор рейса из найденных | F48: TF_choose_available_flight | G48: ='Автоматизированный расчет'!C43 -> 275.89605 | H48: 1100 | I48: =H48/G48 -> 3.9870089 | L48: Выбор рейса из найденных | M48: TF_choose_available_flight | N48: ='Автоматизированный расчет'!C43 -> 275.89605 | P48: =O48/N48 -> 0
E49: Оплата билета | F49: TF_payment_details | G49: ='Автоматизированный расчет'!C44 -> 173.91304 | H49: 692 | I49: =H49/G49 -> 3.979 | L49: Оплата билета | M49: TF_payment_details | N49: ='Автоматизированный расчет'!C44 -> 173.91304 | P49: =O49/N49 -> 0
E50: Просмотр квитанций | F50: TF_itinerary | G50: ='Автоматизированный расчет'!C45 -> 277.83786 | H50: 1105 | I50: =H50/G50 -> 3.9771397 | L50: Просмотр квитанций | M50: TF_itinerary | N50: ='Автоматизированный расчет'!C45 -> 277.83786 | P50: =O50/N50 -> 0
...
